<robot xmlns:xacro="http://www.ros.org/wiki/xacro" name="ndo">
    <!-- Base properties -->
    <xacro:property name="base_width" value="0.25"/>
    <xacro:property name="base_length" value="0.55"/>
    <xacro:property name="base_height" value="0.18"/>

    <!-- Wheel properties -->
    <xacro:property name="wheel_radius" value="0.10"/>
    <xacro:property name="wheel_width" value="0.04"/>
    <xacro:property name="wheel_ygap" value="0.025"/>
    <xacro:property name="wheel_zoff" value="0.05"/>
    <xacro:property name="wheel_front_xoff" value="0.25"/>
    <xacro:property name="wheel_middle_xoff" value="0"/>
    <xacro:property name="wheel_back_xoff" value="-0.25"/>

    <xacro:property name="caster_xoff" value="0.14"/>

    <link name="base_link">
        <visual>
            <geometry>
                <box size="${base_length} ${base_width} ${base_height}"/>
            </geometry>
            <material name="Cyan">
                <color rgba="0 1.0 1.0 1.0"/>
            </material>
        </visual>
    </link>

    <!-- Base footprint of the robot which is the center reference -->
    <link name="base_footprint"/>

    <!-- Joint base_link with base_footprint to place it at ground level -->
    <joint name="base_joint" type="fixed">
        <parent link="base_link"/>
        <child link="base_footprint"/>
        <origin xyz="0.0 0.0 ${-(wheel_radius+wheel_zoff)}" rpy="0 0 0"/>
    </joint>

    <!-- Wheels -->
    <xacro:macro name="wheel" params="prefix x_offset y_reflect">
        <link name="${prefix}_link">
            <visual>
                <origin xyz="0 0 0" rpy="${pi/2} 0 0"/>
                <geometry>
                    <cylinder radius="${wheel_radius}" length="${wheel_width}"/>
                </geometry>
                <material name="Gray">
                <color rgba="0.5 0.5 0.5 1.0"/>
                </material>
            </visual>
        </link>

        <joint name="${prefix}_joint" type="continuous">
            <parent link="base_link"/>
            <child link="${prefix}_link"/>
            <origin xyz="${x_offset} ${y_reflect*(base_width/2+wheel_ygap)} ${-wheel_zoff}" rpy="0 0 0"/>
            <axis xyz="0 1 0"/>
        </joint>
    </xacro:macro>

    <xacro:wheel prefix="frontwhl_l" x_offset="${wheel_front_xoff}" y_reflect="1" />
    <xacro:wheel prefix="frontwhl_r" x_offset="${wheel_front_xoff}" y_reflect="-1" />

    <xacro:wheel prefix="middlewhl_l" x_offset="${wheel_middle_xoff}" y_reflect="1" />
    <xacro:wheel prefix="middlewhl_r" x_offset="${wheel_middle_xoff}" y_reflect="-1" />

    <xacro:wheel prefix="backwhl_l" x_offset="${wheel_back_xoff}" y_reflect="1" />
    <xacro:wheel prefix="backwhl_r" x_offset="${wheel_back_xoff}" y_reflect="-1" />

</robot>